Traceback (most recent call last):
  File "/opt/hostedtoolcache/Python/3.11.12/x64/lib/python3.11/site-packages/jupyter_core/utils/__init__.py", line 154, in wrapped
    asyncio.get_running_loop()
RuntimeError: no running event loop

During handling of the above exception, another exception occurred:

Traceback (most recent call last):
  File "/opt/hostedtoolcache/Python/3.11.12/x64/lib/python3.11/site-packages/jupyter_cache/executors/utils.py", line 58, in single_nb_execution
    executenb(
  File "/opt/hostedtoolcache/Python/3.11.12/x64/lib/python3.11/site-packages/nbclient/client.py", line 1319, in execute
    return NotebookClient(nb=nb, resources=resources, km=km, **kwargs).execute()
           ^^^^^^^^^^^^^^^^^^^^^^^^^^^^^^^^^^^^^^^^^^^^^^^^^^^^^^^^^^^^^^^^^^^^^
  File "/opt/hostedtoolcache/Python/3.11.12/x64/lib/python3.11/site-packages/jupyter_core/utils/__init__.py", line 158, in wrapped
    return loop.run_until_complete(inner)
           ^^^^^^^^^^^^^^^^^^^^^^^^^^^^^^
  File "/opt/hostedtoolcache/Python/3.11.12/x64/lib/python3.11/asyncio/base_events.py", line 654, in run_until_complete
    return future.result()
           ^^^^^^^^^^^^^^^
  File "/opt/hostedtoolcache/Python/3.11.12/x64/lib/python3.11/site-packages/nbclient/client.py", line 709, in async_execute
    await self.async_execute_cell(
  File "/opt/hostedtoolcache/Python/3.11.12/x64/lib/python3.11/site-packages/nbclient/client.py", line 1062, in async_execute_cell
    await self._check_raise_for_error(cell, cell_index, exec_reply)
  File "/opt/hostedtoolcache/Python/3.11.12/x64/lib/python3.11/site-packages/nbclient/client.py", line 918, in _check_raise_for_error
    raise CellExecutionError.from_cell_and_msg(cell, exec_reply_content)
nbclient.exceptions.CellExecutionError: An error occurred while executing the following cell:
------------------
from IPython.core.display import Image 
Image(filename='subplots.png')
------------------


[31m---------------------------------------------------------------------------[39m
[31mFileNotFoundError[39m                         Traceback (most recent call last)
[36mCell[39m[36m [39m[32mIn[14][39m[32m, line 2[39m
[32m      1[39m [38;5;28;01mfrom[39;00m[38;5;250m [39m[34;01mIPython[39;00m[34;01m.[39;00m[34;01mcore[39;00m[34;01m.[39;00m[34;01mdisplay[39;00m[38;5;250m [39m[38;5;28;01mimport[39;00m Image 
[32m----> [39m[32m2[39m [43mImage[49m[43m([49m[43mfilename[49m[43m=[49m[33;43m'[39;49m[33;43msubplots.png[39;49m[33;43m'[39;49m[43m)[49m

[36mFile [39m[32m/opt/hostedtoolcache/Python/3.11.12/x64/lib/python3.11/site-packages/IPython/core/display.py:1025[39m, in [36mImage.__init__[39m[34m(self, data, url, filename, format, embed, width, height, retina, unconfined, metadata, alt)[39m
[32m   1023[39m [38;5;28mself[39m.unconfined = unconfined
[32m   1024[39m [38;5;28mself[39m.alt = alt
[32m-> [39m[32m1025[39m [38;5;28;43msuper[39;49m[43m([49m[43mImage[49m[43m,[49m[43m [49m[38;5;28;43mself[39;49m[43m)[49m[43m.[49m[34;43m__init__[39;49m[43m([49m[43mdata[49m[43m=[49m[43mdata[49m[43m,[49m[43m [49m[43murl[49m[43m=[49m[43murl[49m[43m,[49m[43m [49m[43mfilename[49m[43m=[49m[43mfilename[49m[43m,[49m
[32m   1026[39m [43m        [49m[43mmetadata[49m[43m=[49m[43mmetadata[49m[43m)[49m
[32m   1028[39m [38;5;28;01mif[39;00m [38;5;28mself[39m.width [38;5;129;01mis[39;00m [38;5;28;01mNone[39;00m [38;5;129;01mand[39;00m [38;5;28mself[39m.metadata.get([33m'[39m[33mwidth[39m[33m'[39m, {}):
[32m   1029[39m     [38;5;28mself[39m.width = metadata[[33m'[39m[33mwidth[39m[33m'[39m]

[36mFile [39m[32m/opt/hostedtoolcache/Python/3.11.12/x64/lib/python3.11/site-packages/IPython/core/display.py:343[39m, in [36mDisplayObject.__init__[39m[34m(self, data, url, filename, metadata)[39m
[32m    340[39m [38;5;28;01melif[39;00m [38;5;28mself[39m.metadata [38;5;129;01mis[39;00m [38;5;28;01mNone[39;00m:
[32m    341[39m     [38;5;28mself[39m.metadata = {}
[32m--> [39m[32m343[39m [38;5;28;43mself[39;49m[43m.[49m[43mreload[49m[43m([49m[43m)[49m
[32m    344[39m [38;5;28mself[39m._check_data()

[36mFile [39m[32m/opt/hostedtoolcache/Python/3.11.12/x64/lib/python3.11/site-packages/IPython/core/display.py:1060[39m, in [36mImage.reload[39m[34m(self)[39m
[32m   1058[39m [38;5;250m[39m[33;03m"""Reload the raw data from file or URL."""[39;00m
[32m   1059[39m [38;5;28;01mif[39;00m [38;5;28mself[39m.embed:
[32m-> [39m[32m1060[39m     [38;5;28;43msuper[39;49m[43m([49m[43mImage[49m[43m,[49m[38;5;28;43mself[39;49m[43m)[49m[43m.[49m[43mreload[49m[43m([49m[43m)[49m
[32m   1061[39m     [38;5;28;01mif[39;00m [38;5;28mself[39m.retina:
[32m   1062[39m         [38;5;28mself[39m._retina_shape()

[36mFile [39m[32m/opt/hostedtoolcache/Python/3.11.12/x64/lib/python3.11/site-packages/IPython/core/display.py:369[39m, in [36mDisplayObject.reload[39m[34m(self)[39m
[32m    367[39m [38;5;28;01mif[39;00m [38;5;28mself[39m.filename [38;5;129;01mis[39;00m [38;5;129;01mnot[39;00m [38;5;28;01mNone[39;00m:
[32m    368[39m     encoding = [38;5;28;01mNone[39;00m [38;5;28;01mif[39;00m [33m"[39m[33mb[39m[33m"[39m [38;5;129;01min[39;00m [38;5;28mself[39m._read_flags [38;5;28;01melse[39;00m [33m"[39m[33mutf-8[39m[33m"[39m
[32m--> [39m[32m369[39m     [38;5;28;01mwith[39;00m [38;5;28;43mopen[39;49m[43m([49m[38;5;28;43mself[39;49m[43m.[49m[43mfilename[49m[43m,[49m[43m [49m[38;5;28;43mself[39;49m[43m.[49m[43m_read_flags[49m[43m,[49m[43m [49m[43mencoding[49m[43m=[49m[43mencoding[49m[43m)[49m [38;5;28;01mas[39;00m f:
[32m    370[39m         [38;5;28mself[39m.data = f.read()
[32m    371[39m [38;5;28;01melif[39;00m [38;5;28mself[39m.url [38;5;129;01mis[39;00m [38;5;129;01mnot[39;00m [38;5;28;01mNone[39;00m:
[32m    372[39m     [38;5;66;03m# Deferred import[39;00m

[31mFileNotFoundError[39m: [Errno 2] No such file or directory: 'subplots.png'

