Traceback (most recent call last):
  File "/opt/hostedtoolcache/Python/3.11.7/x64/lib/python3.11/site-packages/jupyter_cache/executors/utils.py", line 58, in single_nb_execution
    executenb(
  File "/opt/hostedtoolcache/Python/3.11.7/x64/lib/python3.11/site-packages/nbclient/client.py", line 1314, in execute
    return NotebookClient(nb=nb, resources=resources, km=km, **kwargs).execute()
           ^^^^^^^^^^^^^^^^^^^^^^^^^^^^^^^^^^^^^^^^^^^^^^^^^^^^^^^^^^^^^^^^^^^^^
  File "/opt/hostedtoolcache/Python/3.11.7/x64/lib/python3.11/site-packages/jupyter_core/utils/__init__.py", line 165, in wrapped
    return loop.run_until_complete(inner)
           ^^^^^^^^^^^^^^^^^^^^^^^^^^^^^^
  File "/opt/hostedtoolcache/Python/3.11.7/x64/lib/python3.11/asyncio/base_events.py", line 653, in run_until_complete
    return future.result()
           ^^^^^^^^^^^^^^^
  File "/opt/hostedtoolcache/Python/3.11.7/x64/lib/python3.11/site-packages/nbclient/client.py", line 709, in async_execute
    await self.async_execute_cell(
  File "/opt/hostedtoolcache/Python/3.11.7/x64/lib/python3.11/site-packages/nbclient/client.py", line 1062, in async_execute_cell
    await self._check_raise_for_error(cell, cell_index, exec_reply)
  File "/opt/hostedtoolcache/Python/3.11.7/x64/lib/python3.11/site-packages/nbclient/client.py", line 918, in _check_raise_for_error
    raise CellExecutionError.from_cell_and_msg(cell, exec_reply_content)
nbclient.exceptions.CellExecutionError: An error occurred while executing the following cell:
------------------
import matplotlib.pyplot as plt
import seaborn as sns
sns.set_context('poster')

x, erf, error = np.getfromtxt('erf_data.txt', unpack=True)
fig, ax = plt.subplots(1, 2)
ax[0].plot(x, erf, '-o', label="err function")
ax[0].legend()
ax[1].plot(x, error, '-s', label="relative error")
ax[1].legend()
ax[1].loglog()
------------------


[0;31m---------------------------------------------------------------------------[0m
[0;31mNameError[0m                                 Traceback (most recent call last)
Cell [0;32mIn[1], line 5[0m
[1;32m      2[0m [38;5;28;01mimport[39;00m [38;5;21;01mseaborn[39;00m [38;5;28;01mas[39;00m [38;5;21;01msns[39;00m
[1;32m      3[0m sns[38;5;241m.[39mset_context([38;5;124m'[39m[38;5;124mposter[39m[38;5;124m'[39m)
[0;32m----> 5[0m x, erf, error [38;5;241m=[39m [43mnp[49m[38;5;241m.[39mgetfromtxt([38;5;124m'[39m[38;5;124merf_data.txt[39m[38;5;124m'[39m, unpack[38;5;241m=[39m[38;5;28;01mTrue[39;00m)
[1;32m      6[0m fig, ax [38;5;241m=[39m plt[38;5;241m.[39msubplots([38;5;241m1[39m, [38;5;241m2[39m)
[1;32m      7[0m ax[[38;5;241m0[39m][38;5;241m.[39mplot(x, erf, [38;5;124m'[39m[38;5;124m-o[39m[38;5;124m'[39m, label[38;5;241m=[39m[38;5;124m"[39m[38;5;124merr function[39m[38;5;124m"[39m)

[0;31mNameError[0m: name 'np' is not defined

